telegram.ext.Updater=ERROR-Error while getting Updates: Conflict: terminated by other getUpdates request; make sure that only one bot instance is running
telegram.ext.Application=ERROR-No error handlers are registered, logging exception.
Traceback (most recent call last):
  File "C:\Python\Lib\site-packages\telegram\ext\_updater.py", line 640, in _network_loop_retry
    if not await action_cb():
           ^^^^^^^^^^^^^^^^^
  File "C:\Python\Lib\site-packages\telegram\ext\_updater.py", line 345, in polling_action_cb
    raise exc
  File "C:\Python\Lib\site-packages\telegram\ext\_updater.py", line 334, in polling_action_cb
    updates = await self.bot.get_updates(
              ^^^^^^^^^^^^^^^^^^^^^^^^^^^
  File "C:\Python\Lib\site-packages\telegram\ext\_extbot.py", line 565, in get_updates
    updates = await super().get_updates(
              ^^^^^^^^^^^^^^^^^^^^^^^^^^
  File "C:\Python\Lib\site-packages\telegram\_bot.py", line 519, in decorator
    result = await func(self, *args, **kwargs)  # skipcq: PYL-E1102
             ^^^^^^^^^^^^^^^^^^^^^^^^^^^^^^^^^
  File "C:\Python\Lib\site-packages\telegram\_bot.py", line 3562, in get_updates
    await self._post(
  File "C:\Python\Lib\site-packages\telegram\_bot.py", line 607, in _post
    return await self._do_post(
           ^^^^^^^^^^^^^^^^^^^^
  File "C:\Python\Lib\site-packages\telegram\ext\_extbot.py", line 347, in _do_post
    return await super()._do_post(
           ^^^^^^^^^^^^^^^^^^^^^^^
  File "C:\Python\Lib\site-packages\telegram\_bot.py", line 635, in _do_post
    return await request.post(
           ^^^^^^^^^^^^^^^^^^^
  File "C:\Python\Lib\site-packages\telegram\request\_baserequest.py", line 168, in post
    result = await self._request_wrapper(
             ^^^^^^^^^^^^^^^^^^^^^^^^^^^^
  File "C:\Python\Lib\site-packages\telegram\request\_baserequest.py", line 327, in _request_wrapper
    raise Conflict(message)
telegram.error.Conflict: Conflict: terminated by other getUpdates request; make sure that only one bot instance is running
telegram.ext.Updater=ERROR-Error while getting Updates: Conflict: terminated by other getUpdates request; make sure that only one bot instance is running
telegram.ext.Application=ERROR-No error handlers are registered, logging exception.
Traceback (most recent call last):
  File "C:\Python\Lib\site-packages\telegram\ext\_updater.py", line 640, in _network_loop_retry
    if not await action_cb():
           ^^^^^^^^^^^^^^^^^
  File "C:\Python\Lib\site-packages\telegram\ext\_updater.py", line 345, in polling_action_cb
    raise exc
  File "C:\Python\Lib\site-packages\telegram\ext\_updater.py", line 334, in polling_action_cb
    updates = await self.bot.get_updates(
              ^^^^^^^^^^^^^^^^^^^^^^^^^^^
  File "C:\Python\Lib\site-packages\telegram\ext\_extbot.py", line 565, in get_updates
    updates = await super().get_updates(
              ^^^^^^^^^^^^^^^^^^^^^^^^^^
  File "C:\Python\Lib\site-packages\telegram\_bot.py", line 519, in decorator
    result = await func(self, *args, **kwargs)  # skipcq: PYL-E1102
             ^^^^^^^^^^^^^^^^^^^^^^^^^^^^^^^^^
  File "C:\Python\Lib\site-packages\telegram\_bot.py", line 3562, in get_updates
    await self._post(
  File "C:\Python\Lib\site-packages\telegram\_bot.py", line 607, in _post
    return await self._do_post(
           ^^^^^^^^^^^^^^^^^^^^
  File "C:\Python\Lib\site-packages\telegram\ext\_extbot.py", line 347, in _do_post
    return await super()._do_post(
           ^^^^^^^^^^^^^^^^^^^^^^^
  File "C:\Python\Lib\site-packages\telegram\_bot.py", line 635, in _do_post
    return await request.post(
           ^^^^^^^^^^^^^^^^^^^
  File "C:\Python\Lib\site-packages\telegram\request\_baserequest.py", line 168, in post
    result = await self._request_wrapper(
             ^^^^^^^^^^^^^^^^^^^^^^^^^^^^
  File "C:\Python\Lib\site-packages\telegram\request\_baserequest.py", line 327, in _request_wrapper
    raise Conflict(message)
telegram.error.Conflict: Conflict: terminated by other getUpdates request; make sure that only one bot instance is running
telegram.ext.Updater=ERROR-Error while getting Updates: Conflict: terminated by other getUpdates request; make sure that only one bot instance is running
telegram.ext.Application=ERROR-No error handlers are registered, logging exception.
Traceback (most recent call last):
  File "C:\Python\Lib\site-packages\telegram\ext\_updater.py", line 640, in _network_loop_retry
    if not await action_cb():
           ^^^^^^^^^^^^^^^^^
  File "C:\Python\Lib\site-packages\telegram\ext\_updater.py", line 345, in polling_action_cb
    raise exc
  File "C:\Python\Lib\site-packages\telegram\ext\_updater.py", line 334, in polling_action_cb
    updates = await self.bot.get_updates(
              ^^^^^^^^^^^^^^^^^^^^^^^^^^^
  File "C:\Python\Lib\site-packages\telegram\ext\_extbot.py", line 565, in get_updates
    updates = await super().get_updates(
              ^^^^^^^^^^^^^^^^^^^^^^^^^^
  File "C:\Python\Lib\site-packages\telegram\_bot.py", line 519, in decorator
    result = await func(self, *args, **kwargs)  # skipcq: PYL-E1102
             ^^^^^^^^^^^^^^^^^^^^^^^^^^^^^^^^^
  File "C:\Python\Lib\site-packages\telegram\_bot.py", line 3562, in get_updates
    await self._post(
  File "C:\Python\Lib\site-packages\telegram\_bot.py", line 607, in _post
    return await self._do_post(
           ^^^^^^^^^^^^^^^^^^^^
  File "C:\Python\Lib\site-packages\telegram\ext\_extbot.py", line 347, in _do_post
    return await super()._do_post(
           ^^^^^^^^^^^^^^^^^^^^^^^
  File "C:\Python\Lib\site-packages\telegram\_bot.py", line 635, in _do_post
    return await request.post(
           ^^^^^^^^^^^^^^^^^^^
  File "C:\Python\Lib\site-packages\telegram\request\_baserequest.py", line 168, in post
    result = await self._request_wrapper(
             ^^^^^^^^^^^^^^^^^^^^^^^^^^^^
  File "C:\Python\Lib\site-packages\telegram\request\_baserequest.py", line 327, in _request_wrapper
    raise Conflict(message)
telegram.error.Conflict: Conflict: terminated by other getUpdates request; make sure that only one bot instance is running
telegram.ext.Updater=ERROR-Error while getting Updates: Conflict: terminated by other getUpdates request; make sure that only one bot instance is running
telegram.ext.Application=ERROR-No error handlers are registered, logging exception.
Traceback (most recent call last):
  File "C:\Python\Lib\site-packages\telegram\ext\_updater.py", line 640, in _network_loop_retry
    if not await action_cb():
           ^^^^^^^^^^^^^^^^^
  File "C:\Python\Lib\site-packages\telegram\ext\_updater.py", line 345, in polling_action_cb
    raise exc
  File "C:\Python\Lib\site-packages\telegram\ext\_updater.py", line 334, in polling_action_cb
    updates = await self.bot.get_updates(
              ^^^^^^^^^^^^^^^^^^^^^^^^^^^
  File "C:\Python\Lib\site-packages\telegram\ext\_extbot.py", line 565, in get_updates
    updates = await super().get_updates(
              ^^^^^^^^^^^^^^^^^^^^^^^^^^
  File "C:\Python\Lib\site-packages\telegram\_bot.py", line 519, in decorator
    result = await func(self, *args, **kwargs)  # skipcq: PYL-E1102
             ^^^^^^^^^^^^^^^^^^^^^^^^^^^^^^^^^
  File "C:\Python\Lib\site-packages\telegram\_bot.py", line 3562, in get_updates
    await self._post(
  File "C:\Python\Lib\site-packages\telegram\_bot.py", line 607, in _post
    return await self._do_post(
           ^^^^^^^^^^^^^^^^^^^^
  File "C:\Python\Lib\site-packages\telegram\ext\_extbot.py", line 347, in _do_post
    return await super()._do_post(
           ^^^^^^^^^^^^^^^^^^^^^^^
  File "C:\Python\Lib\site-packages\telegram\_bot.py", line 635, in _do_post
    return await request.post(
           ^^^^^^^^^^^^^^^^^^^
  File "C:\Python\Lib\site-packages\telegram\request\_baserequest.py", line 168, in post
    result = await self._request_wrapper(
             ^^^^^^^^^^^^^^^^^^^^^^^^^^^^
  File "C:\Python\Lib\site-packages\telegram\request\_baserequest.py", line 327, in _request_wrapper
    raise Conflict(message)
telegram.error.Conflict: Conflict: terminated by other getUpdates request; make sure that only one bot instance is running
telegram.ext.Updater=ERROR-Error while getting Updates: Conflict: terminated by other getUpdates request; make sure that only one bot instance is running
telegram.ext.Application=ERROR-No error handlers are registered, logging exception.
Traceback (most recent call last):
  File "C:\Python\Lib\site-packages\telegram\ext\_updater.py", line 640, in _network_loop_retry
    if not await action_cb():
           ^^^^^^^^^^^^^^^^^
  File "C:\Python\Lib\site-packages\telegram\ext\_updater.py", line 345, in polling_action_cb
    raise exc
  File "C:\Python\Lib\site-packages\telegram\ext\_updater.py", line 334, in polling_action_cb
    updates = await self.bot.get_updates(
              ^^^^^^^^^^^^^^^^^^^^^^^^^^^
  File "C:\Python\Lib\site-packages\telegram\ext\_extbot.py", line 565, in get_updates
    updates = await super().get_updates(
              ^^^^^^^^^^^^^^^^^^^^^^^^^^
  File "C:\Python\Lib\site-packages\telegram\_bot.py", line 519, in decorator
    result = await func(self, *args, **kwargs)  # skipcq: PYL-E1102
             ^^^^^^^^^^^^^^^^^^^^^^^^^^^^^^^^^
  File "C:\Python\Lib\site-packages\telegram\_bot.py", line 3562, in get_updates
    await self._post(
  File "C:\Python\Lib\site-packages\telegram\_bot.py", line 607, in _post
    return await self._do_post(
           ^^^^^^^^^^^^^^^^^^^^
  File "C:\Python\Lib\site-packages\telegram\ext\_extbot.py", line 347, in _do_post
    return await super()._do_post(
           ^^^^^^^^^^^^^^^^^^^^^^^
  File "C:\Python\Lib\site-packages\telegram\_bot.py", line 635, in _do_post
    return await request.post(
           ^^^^^^^^^^^^^^^^^^^
  File "C:\Python\Lib\site-packages\telegram\request\_baserequest.py", line 168, in post
    result = await self._request_wrapper(
             ^^^^^^^^^^^^^^^^^^^^^^^^^^^^
  File "C:\Python\Lib\site-packages\telegram\request\_baserequest.py", line 327, in _request_wrapper
    raise Conflict(message)
telegram.error.Conflict: Conflict: terminated by other getUpdates request; make sure that only one bot instance is running
telegram.ext.Updater=ERROR-Error while getting Updates: Conflict: terminated by other getUpdates request; make sure that only one bot instance is running
telegram.ext.Application=ERROR-No error handlers are registered, logging exception.
Traceback (most recent call last):
  File "C:\Python\Lib\site-packages\telegram\ext\_updater.py", line 640, in _network_loop_retry
    if not await action_cb():
           ^^^^^^^^^^^^^^^^^
  File "C:\Python\Lib\site-packages\telegram\ext\_updater.py", line 345, in polling_action_cb
    raise exc
  File "C:\Python\Lib\site-packages\telegram\ext\_updater.py", line 334, in polling_action_cb
    updates = await self.bot.get_updates(
              ^^^^^^^^^^^^^^^^^^^^^^^^^^^
  File "C:\Python\Lib\site-packages\telegram\ext\_extbot.py", line 565, in get_updates
    updates = await super().get_updates(
              ^^^^^^^^^^^^^^^^^^^^^^^^^^
  File "C:\Python\Lib\site-packages\telegram\_bot.py", line 519, in decorator
    result = await func(self, *args, **kwargs)  # skipcq: PYL-E1102
             ^^^^^^^^^^^^^^^^^^^^^^^^^^^^^^^^^
  File "C:\Python\Lib\site-packages\telegram\_bot.py", line 3562, in get_updates
    await self._post(
  File "C:\Python\Lib\site-packages\telegram\_bot.py", line 607, in _post
    return await self._do_post(
           ^^^^^^^^^^^^^^^^^^^^
  File "C:\Python\Lib\site-packages\telegram\ext\_extbot.py", line 347, in _do_post
    return await super()._do_post(
           ^^^^^^^^^^^^^^^^^^^^^^^
  File "C:\Python\Lib\site-packages\telegram\_bot.py", line 635, in _do_post
    return await request.post(
           ^^^^^^^^^^^^^^^^^^^
  File "C:\Python\Lib\site-packages\telegram\request\_baserequest.py", line 168, in post
    result = await self._request_wrapper(
             ^^^^^^^^^^^^^^^^^^^^^^^^^^^^
  File "C:\Python\Lib\site-packages\telegram\request\_baserequest.py", line 327, in _request_wrapper
    raise Conflict(message)
telegram.error.Conflict: Conflict: terminated by other getUpdates request; make sure that only one bot instance is running
telegram.ext.Updater=ERROR-Error while getting Updates: Conflict: terminated by other getUpdates request; make sure that only one bot instance is running
telegram.ext.Application=ERROR-No error handlers are registered, logging exception.
Traceback (most recent call last):
  File "C:\Python\Lib\site-packages\telegram\ext\_updater.py", line 640, in _network_loop_retry
    if not await action_cb():
           ^^^^^^^^^^^^^^^^^
  File "C:\Python\Lib\site-packages\telegram\ext\_updater.py", line 345, in polling_action_cb
    raise exc
  File "C:\Python\Lib\site-packages\telegram\ext\_updater.py", line 334, in polling_action_cb
    updates = await self.bot.get_updates(
              ^^^^^^^^^^^^^^^^^^^^^^^^^^^
  File "C:\Python\Lib\site-packages\telegram\ext\_extbot.py", line 565, in get_updates
    updates = await super().get_updates(
              ^^^^^^^^^^^^^^^^^^^^^^^^^^
  File "C:\Python\Lib\site-packages\telegram\_bot.py", line 519, in decorator
    result = await func(self, *args, **kwargs)  # skipcq: PYL-E1102
             ^^^^^^^^^^^^^^^^^^^^^^^^^^^^^^^^^
  File "C:\Python\Lib\site-packages\telegram\_bot.py", line 3562, in get_updates
    await self._post(
  File "C:\Python\Lib\site-packages\telegram\_bot.py", line 607, in _post
    return await self._do_post(
           ^^^^^^^^^^^^^^^^^^^^
  File "C:\Python\Lib\site-packages\telegram\ext\_extbot.py", line 347, in _do_post
    return await super()._do_post(
           ^^^^^^^^^^^^^^^^^^^^^^^
  File "C:\Python\Lib\site-packages\telegram\_bot.py", line 635, in _do_post
    return await request.post(
           ^^^^^^^^^^^^^^^^^^^
  File "C:\Python\Lib\site-packages\telegram\request\_baserequest.py", line 168, in post
    result = await self._request_wrapper(
             ^^^^^^^^^^^^^^^^^^^^^^^^^^^^
  File "C:\Python\Lib\site-packages\telegram\request\_baserequest.py", line 327, in _request_wrapper
    raise Conflict(message)
telegram.error.Conflict: Conflict: terminated by other getUpdates request; make sure that only one bot instance is running
telegram.ext.Updater=ERROR-Error while getting Updates: Conflict: terminated by other getUpdates request; make sure that only one bot instance is running
telegram.ext.Application=ERROR-No error handlers are registered, logging exception.
Traceback (most recent call last):
  File "C:\Python\Lib\site-packages\telegram\ext\_updater.py", line 640, in _network_loop_retry
    if not await action_cb():
           ^^^^^^^^^^^^^^^^^
  File "C:\Python\Lib\site-packages\telegram\ext\_updater.py", line 345, in polling_action_cb
    raise exc
  File "C:\Python\Lib\site-packages\telegram\ext\_updater.py", line 334, in polling_action_cb
    updates = await self.bot.get_updates(
              ^^^^^^^^^^^^^^^^^^^^^^^^^^^
  File "C:\Python\Lib\site-packages\telegram\ext\_extbot.py", line 565, in get_updates
    updates = await super().get_updates(
              ^^^^^^^^^^^^^^^^^^^^^^^^^^
  File "C:\Python\Lib\site-packages\telegram\_bot.py", line 519, in decorator
    result = await func(self, *args, **kwargs)  # skipcq: PYL-E1102
             ^^^^^^^^^^^^^^^^^^^^^^^^^^^^^^^^^
  File "C:\Python\Lib\site-packages\telegram\_bot.py", line 3562, in get_updates
    await self._post(
  File "C:\Python\Lib\site-packages\telegram\_bot.py", line 607, in _post
    return await self._do_post(
           ^^^^^^^^^^^^^^^^^^^^
  File "C:\Python\Lib\site-packages\telegram\ext\_extbot.py", line 347, in _do_post
    return await super()._do_post(
           ^^^^^^^^^^^^^^^^^^^^^^^
  File "C:\Python\Lib\site-packages\telegram\_bot.py", line 635, in _do_post
    return await request.post(
           ^^^^^^^^^^^^^^^^^^^
  File "C:\Python\Lib\site-packages\telegram\request\_baserequest.py", line 168, in post
    result = await self._request_wrapper(
             ^^^^^^^^^^^^^^^^^^^^^^^^^^^^
  File "C:\Python\Lib\site-packages\telegram\request\_baserequest.py", line 327, in _request_wrapper
    raise Conflict(message)
telegram.error.Conflict: Conflict: terminated by other getUpdates request; make sure that only one bot instance is running
telegram.ext.Updater=ERROR-Error while getting Updates: Conflict: terminated by other getUpdates request; make sure that only one bot instance is running
telegram.ext.Application=ERROR-No error handlers are registered, logging exception.
Traceback (most recent call last):
  File "C:\Python\Lib\site-packages\telegram\ext\_updater.py", line 640, in _network_loop_retry
    if not await action_cb():
           ^^^^^^^^^^^^^^^^^
  File "C:\Python\Lib\site-packages\telegram\ext\_updater.py", line 345, in polling_action_cb
    raise exc
  File "C:\Python\Lib\site-packages\telegram\ext\_updater.py", line 334, in polling_action_cb
    updates = await self.bot.get_updates(
              ^^^^^^^^^^^^^^^^^^^^^^^^^^^
  File "C:\Python\Lib\site-packages\telegram\ext\_extbot.py", line 565, in get_updates
    updates = await super().get_updates(
              ^^^^^^^^^^^^^^^^^^^^^^^^^^
  File "C:\Python\Lib\site-packages\telegram\_bot.py", line 519, in decorator
    result = await func(self, *args, **kwargs)  # skipcq: PYL-E1102
             ^^^^^^^^^^^^^^^^^^^^^^^^^^^^^^^^^
  File "C:\Python\Lib\site-packages\telegram\_bot.py", line 3562, in get_updates
    await self._post(
  File "C:\Python\Lib\site-packages\telegram\_bot.py", line 607, in _post
    return await self._do_post(
           ^^^^^^^^^^^^^^^^^^^^
  File "C:\Python\Lib\site-packages\telegram\ext\_extbot.py", line 347, in _do_post
    return await super()._do_post(
           ^^^^^^^^^^^^^^^^^^^^^^^
  File "C:\Python\Lib\site-packages\telegram\_bot.py", line 635, in _do_post
    return await request.post(
           ^^^^^^^^^^^^^^^^^^^
  File "C:\Python\Lib\site-packages\telegram\request\_baserequest.py", line 168, in post
    result = await self._request_wrapper(
             ^^^^^^^^^^^^^^^^^^^^^^^^^^^^
  File "C:\Python\Lib\site-packages\telegram\request\_baserequest.py", line 327, in _request_wrapper
    raise Conflict(message)
telegram.error.Conflict: Conflict: terminated by other getUpdates request; make sure that only one bot instance is running
telegram.ext.Updater=ERROR-Error while getting Updates: Conflict: terminated by other getUpdates request; make sure that only one bot instance is running
telegram.ext.Application=ERROR-No error handlers are registered, logging exception.
Traceback (most recent call last):
  File "C:\Python\Lib\site-packages\telegram\ext\_updater.py", line 640, in _network_loop_retry
    if not await action_cb():
           ^^^^^^^^^^^^^^^^^
  File "C:\Python\Lib\site-packages\telegram\ext\_updater.py", line 345, in polling_action_cb
    raise exc
  File "C:\Python\Lib\site-packages\telegram\ext\_updater.py", line 334, in polling_action_cb
    updates = await self.bot.get_updates(
              ^^^^^^^^^^^^^^^^^^^^^^^^^^^
  File "C:\Python\Lib\site-packages\telegram\ext\_extbot.py", line 565, in get_updates
    updates = await super().get_updates(
              ^^^^^^^^^^^^^^^^^^^^^^^^^^
  File "C:\Python\Lib\site-packages\telegram\_bot.py", line 519, in decorator
    result = await func(self, *args, **kwargs)  # skipcq: PYL-E1102
             ^^^^^^^^^^^^^^^^^^^^^^^^^^^^^^^^^
  File "C:\Python\Lib\site-packages\telegram\_bot.py", line 3562, in get_updates
    await self._post(
  File "C:\Python\Lib\site-packages\telegram\_bot.py", line 607, in _post
    return await self._do_post(
           ^^^^^^^^^^^^^^^^^^^^
  File "C:\Python\Lib\site-packages\telegram\ext\_extbot.py", line 347, in _do_post
    return await super()._do_post(
           ^^^^^^^^^^^^^^^^^^^^^^^
  File "C:\Python\Lib\site-packages\telegram\_bot.py", line 635, in _do_post
    return await request.post(
           ^^^^^^^^^^^^^^^^^^^
  File "C:\Python\Lib\site-packages\telegram\request\_baserequest.py", line 168, in post
    result = await self._request_wrapper(
             ^^^^^^^^^^^^^^^^^^^^^^^^^^^^
  File "C:\Python\Lib\site-packages\telegram\request\_baserequest.py", line 327, in _request_wrapper
    raise Conflict(message)
telegram.error.Conflict: Conflict: terminated by other getUpdates request; make sure that only one bot instance is running
telegram.ext.Updater=ERROR-Error while getting Updates: Conflict: terminated by other getUpdates request; make sure that only one bot instance is running
telegram.ext.Application=ERROR-No error handlers are registered, logging exception.
Traceback (most recent call last):
  File "C:\Python\Lib\site-packages\telegram\ext\_updater.py", line 640, in _network_loop_retry
    if not await action_cb():
           ^^^^^^^^^^^^^^^^^
  File "C:\Python\Lib\site-packages\telegram\ext\_updater.py", line 345, in polling_action_cb
    raise exc
  File "C:\Python\Lib\site-packages\telegram\ext\_updater.py", line 334, in polling_action_cb
    updates = await self.bot.get_updates(
              ^^^^^^^^^^^^^^^^^^^^^^^^^^^
  File "C:\Python\Lib\site-packages\telegram\ext\_extbot.py", line 565, in get_updates
    updates = await super().get_updates(
              ^^^^^^^^^^^^^^^^^^^^^^^^^^
  File "C:\Python\Lib\site-packages\telegram\_bot.py", line 519, in decorator
    result = await func(self, *args, **kwargs)  # skipcq: PYL-E1102
             ^^^^^^^^^^^^^^^^^^^^^^^^^^^^^^^^^
  File "C:\Python\Lib\site-packages\telegram\_bot.py", line 3562, in get_updates
    await self._post(
  File "C:\Python\Lib\site-packages\telegram\_bot.py", line 607, in _post
    return await self._do_post(
           ^^^^^^^^^^^^^^^^^^^^
  File "C:\Python\Lib\site-packages\telegram\ext\_extbot.py", line 347, in _do_post
    return await super()._do_post(
           ^^^^^^^^^^^^^^^^^^^^^^^
  File "C:\Python\Lib\site-packages\telegram\_bot.py", line 635, in _do_post
    return await request.post(
           ^^^^^^^^^^^^^^^^^^^
  File "C:\Python\Lib\site-packages\telegram\request\_baserequest.py", line 168, in post
    result = await self._request_wrapper(
             ^^^^^^^^^^^^^^^^^^^^^^^^^^^^
  File "C:\Python\Lib\site-packages\telegram\request\_baserequest.py", line 327, in _request_wrapper
    raise Conflict(message)
telegram.error.Conflict: Conflict: terminated by other getUpdates request; make sure that only one bot instance is running
telegram.ext.Updater=ERROR-Error while getting Updates: Conflict: terminated by other getUpdates request; make sure that only one bot instance is running
telegram.ext.Application=ERROR-No error handlers are registered, logging exception.
Traceback (most recent call last):
  File "C:\Python\Lib\site-packages\telegram\ext\_updater.py", line 640, in _network_loop_retry
    if not await action_cb():
           ^^^^^^^^^^^^^^^^^
  File "C:\Python\Lib\site-packages\telegram\ext\_updater.py", line 345, in polling_action_cb
    raise exc
  File "C:\Python\Lib\site-packages\telegram\ext\_updater.py", line 334, in polling_action_cb
    updates = await self.bot.get_updates(
              ^^^^^^^^^^^^^^^^^^^^^^^^^^^
  File "C:\Python\Lib\site-packages\telegram\ext\_extbot.py", line 565, in get_updates
    updates = await super().get_updates(
              ^^^^^^^^^^^^^^^^^^^^^^^^^^
  File "C:\Python\Lib\site-packages\telegram\_bot.py", line 519, in decorator
    result = await func(self, *args, **kwargs)  # skipcq: PYL-E1102
             ^^^^^^^^^^^^^^^^^^^^^^^^^^^^^^^^^
  File "C:\Python\Lib\site-packages\telegram\_bot.py", line 3562, in get_updates
    await self._post(
  File "C:\Python\Lib\site-packages\telegram\_bot.py", line 607, in _post
    return await self._do_post(
           ^^^^^^^^^^^^^^^^^^^^
  File "C:\Python\Lib\site-packages\telegram\ext\_extbot.py", line 347, in _do_post
    return await super()._do_post(
           ^^^^^^^^^^^^^^^^^^^^^^^
  File "C:\Python\Lib\site-packages\telegram\_bot.py", line 635, in _do_post
    return await request.post(
           ^^^^^^^^^^^^^^^^^^^
  File "C:\Python\Lib\site-packages\telegram\request\_baserequest.py", line 168, in post
    result = await self._request_wrapper(
             ^^^^^^^^^^^^^^^^^^^^^^^^^^^^
  File "C:\Python\Lib\site-packages\telegram\request\_baserequest.py", line 327, in _request_wrapper
    raise Conflict(message)
telegram.error.Conflict: Conflict: terminated by other getUpdates request; make sure that only one bot instance is running
